<?xml version="1.0"?>


<robot name="robosys">



	<link name="base_link"/>
	
	<joint name="world_joint" type="fixed">
		<parent link="base_link"/>
		<child link="body"/>
		<origin rpy="0 0 0" xyz="0 0 1"/>
	</joint>


	<link name="body">
		<visual>
			<geometry>
				<box size="0.2 0.1 0.1"/>
			</geometry>
			<origin xyz="0 0 0"/>
		</visual>
		<collision>
			<geometry>
				<box size="0.2 0.1 0.1"/>
			</geometry>
		</collision>
		<inertial>
			<mass value="1.0"/>
			<inertia ixx="0.001666" iyy="0.004166666" izz="0.004166666" ixy="0" ixz="0" iyz="0"/>
		</inertial>


	</link>
	
	<link name="center_link">
		<visual>
			<geometry>
				<box size="0.05 0.025 0.025"/>
			</geometry>
			<origin rpy="0 0 0" xyz="-0.02 0 -0.0125"/>
		</visual>
		<collision>
			<geometry>
				<box size="0.05 0.025 0.025"/>
			</geometry>
			<origin rpy="0 0 0" xyz="-0.02 0 -0.0125"/>
		</collision>
		<inertial>
			<mass value="1.0"/>
			<inertia ixx="0.001666" iyy="0.004166666" izz="0.004166666" ixy="0" ixz="0" iyz="0"/>
		</inertial>


	</link>
	
	
	<joint name="center_link_j" type="continuous">
		<axis xyz="0 0 1"/>
		<parent link="body"/>
		<child link="center_link"/>
		<origin rpy="0 0 0" xyz="0.095 0 -0.05"/>
	</joint>


	<link name="center_wheel">
		<visual>
			<geometry>
				<cylinder length="0.04" radius="0.0175"/>
			</geometry>
			<origin rpy="-1.5708 0 0" xyz="0 0 0"/>
		</visual>
		<collision>
			<geometry>
				<cylinder length="0.04" radius="0.0175"/>
			</geometry>
			<origin rpy="-1.5708 0 0" xyz="0 0 0"/>

		</collision>
		<inertial>
			<mass value="0.5"/>
			<inertia ixx="0.02066666" iyy="0.02066666" izz="0.04" ixy="0" ixz="0" iyz="0"/>
		</inertial>



	</link>
	
		
	
	<joint name="center_wheel_j" type="continuous">
		<axis xyz="0 1 0"/>
		<parent link="center_link"/>
		<child link="center_wheel"/>
		<origin rpy="0 0 0" xyz="-0.04 0 -0.0125"/>
	</joint>



	<link name="right_wheel">
		<visual>
			<geometry>
				<cylinder length="0.04" radius="0.08"/>
			</geometry>
			<origin rpy="-1.5708 0 0" xyz="0 0.02 0"/>
		</visual>
		<collision>
			<geometry>
				<cylinder length="0.04" radius="0.08"/>
			</geometry>
			<origin rpy="-1.5708 0 0" xyz="0 0.02 0"/>

		</collision>
		<inertial>
			<mass value="0.5"/>
			<inertia ixx="0.02066666" iyy="0.02066666" izz="0.04" ixy="0" ixz="0" iyz="0"/>
		</inertial>

	</link>
	
	<joint name="right_j" type="continuous">
		<axis xyz="0 1 0"/>
		<parent link="body"/>
		<child link="right_wheel"/>
		<origin rpy="0 0 0" xyz="-0.05 0.06 0"/>
	</joint>

	<link name="left_wheel">
		<visual>
			<geometry>
				<cylinder length="0.04" radius="0.08"/>
			</geometry>
			<origin rpy="1.5708 0 0" xyz="0 -0.02 0"/>
		</visual>
		<collision>
			<geometry>
				<cylinder length="0.04" radius="0.08"/>
			</geometry>
			<origin rpy="1.5708 0 0" xyz="0 -0.02 0"/>
		</collision>
		<inertial>
			<mass value="0.5"/>
			<inertia ixx="0.02066666" iyy="0.02066666" izz="0.04" ixy="0" ixz="0" iyz="0"/>
		</inertial>



	</link>

	

	<joint name="left_j" type="continuous">
		<axis xyz="0 1 0"/>
		<parent link="body"/>
		<child link="left_wheel"/>
		<origin rpy="0 0 0" xyz="-0.05 -0.06 0"/>
	</joint>

	<!-- Setting of Depth Sensor Link and Joint -->
	<link name="depth_link">
		<visual>
			<geometry>
				<box size="0.01 0.01 0.01"/>	
			</geometry>
		</visual>
		<collision>
			<geometry>
				<box size="0.01 0.01 0.01"/>	
			</geometry>
		</collision>
		<inertial>
			<mass value="0.1"/>
			<inertia ixx="0.005208" ixy="0.0" ixz="0.0" iyy="0.005208" iyz="0.0" izz="0.005208"/>
		</inertial>
	</link>




	<joint name="depth_base_joint" type="fixed">
		<axis xyz="0 1 0"/>
		<origin rpy="0 0 0" xyz="0.1 0 0.055"/>
		<parent link="body"/>
		<child link="depth_link"/>
	</joint>




		




	<transmission name="t_right">
		<type>transmission_interface/SimpleTransmission</type>
		<joint name="right_j">
			<hardwareInterface>hardware_interface/VelocityJointInterface</hardwareInterface>
		</joint>
		<actuator name="m_right">
			<hardwareInterface>hardware_interface/VelocityJointInterface</hardwareInterface>
			<mechanicalReduction>1</mechanicalReduction>
		</actuator>
	</transmission>
	
	<transmission name="t_left">
		<type>transmission_interface/SimpleTransmission</type>
		<joint name="left_j">
			<hardwareInterface>hardware_interface/VelocityJointInterface</hardwareInterface>
		</joint>
		<actuator name="m_left">
			<hardwareInterface>hardware_interface/VelocityJointInterface</hardwareInterface>
			<mechanicalReduction>1</mechanicalReduction>
		</actuator>
	</transmission>


	<gazebo reference="body">
		<mu1 value="0.3"/>
		<mu2 value="0.3"/>
	</gazebo>

	<gazebo reference="right_wheel">
		<mu1 value="0.3"/>
		<mu2 value="0.3"/>
	</gazebo>

	<gazebo reference="left_wheel">
		<mu1 value="0.3"/>
		<mu2 value="0.3"/>
	</gazebo>

	<gazebo reference="depth_link">
		<mu1 value="0.3"/>
		<mu1 value="0.3"/>
	</gazebo>

	<gazebo  reference="center_link">
		<mu1 value="0.3"/>
		<mu2 value="0.3"/>
	</gazebo>

	<gazebo  reference="center_wheel">
		<mu1 value="0.3"/>
		<mu2 value="0.3"/>
	</gazebo>






	<gazebo>

		<plugin name="ros_control" filename="libgazebo_ros_control.so">
			<robotNamespace>robosys</robotNamespace>
		
		</plugin>
	</gazebo>

	<gazebo reference="depth_link">
		<sensor type="depth" name="Dcamera">
			<always_on>true</always_on>
			<update_rate>0.0</update_rate>
			<camera>
				<horizontal_fov>2</horizontal_fov>
				<image>
					<format>L8</format>
					<width>640</width>
					<height>480</height>
				</image>
				<clip>
					<near>0.5</near>
					<far>3.0</far>
				</clip>
			</camera>

			<plugin name="depth_link_controller" filename="libgazebo_ros_openni_kinect.so">
				<alwaysOn>true</alwaysOn>
				<updateRate>1.0</updateRate>
				<cameraName>Dcamera</cameraName>
				<depthImageTopicName>depth/image_raw</depthImageTopicName>
				<imageTopicName>rgb/image_raw</imageTopicName>
				<depthImageCameraInfoTopicName>depth/camera_info</depthImageCameraInfoTopicName>
				<pointCloudTopicName>depth/points</pointCloudTopicName>
				<cameraInfoTopicName>rgb/camera_info</cameraInfoTopicName>
				<frameName>depth_link</frameName>
				<baseline>0.1</baseline>
				<pointCloudCutoff>0.5</pointCloudCutoff>
				<distortionk1>0.00000001</distortionk1>
				<distortionk2>0.00000001</distortionk2>
				<distortionk3>0.00000001</distortionk3>
				<distortionT1>0.00000001</distortionT1>
				<distortionT2>0.00000001</distortionT2>
			</plugin>
		</sensor>
		<material value="Gazebo/Blue"/>
	</gazebo>







	
		

</robot>


